<mujoco model="h1">
  <compiler autolimits="true" angle="radian"/>
  <size njmax="-1" nconmax="-1" nuser_actuator="-1"/>
  <visual>
    <global azimuth="160" elevation="-20"/>
    <headlight ambient="0.3 0.3 0.3" diffuse="0.6 0.6 0.6" specular="0 0 0"/>
    <rgba haze="0.15 0.25 0.35 1"/>
  </visual>
  <statistic meansize="0.05" extent="1.8" center="0 0 1"/>
  <default>
    <default class="/">
      <default class="h1">
        <joint limited="false" armature="0.1" damping="1"/>
        <site group="4" rgba="0.5 0.5 0.5 0.3" size="0.001"/>
        <motor ctrllimited="false"/>
        <default class="visual">
          <geom type="mesh" contype="0" conaffinity="0" group="1" material="black"/>
        </default>
        <default class="collision">
          <geom group="1" mass="0" density="0"/>
          <default class="foot">
            <geom type="capsule" size="0.014"/>
            <default class="foot1">
              <geom fromto="-0.035 0 -0.056 0.02 0 -0.045"/>
            </default>
            <default class="foot2">
              <geom fromto="0.02 0 -0.045 0.115 0 -0.056"/>
            </default>
            <default class="foot3">
              <geom fromto="0.14 -0.03 -0.056 0.14 0.03 -0.056"/>
            </default>
          </default>
        </default>
      </default>
    </default>
  </default>
  <asset>
    <texture name="//unnamed_texture_0" type="skybox" builtin="gradient" rgb1="0.3 0.5 0.7" rgb2="0 0 0" width="512" height="3072"/>
    <texture name="groundplane" type="2d" builtin="checker" rgb1="0.2 0.3 0.4" rgb2="0.1 0.2 0.3" mark="edge" markrgb="0.8 0.8 0.8" width="300" height="300"/>
    <material name="groundplane" class="/" texture="groundplane" texrepeat="5 5" texuniform="true" reflectance="0.2"/>
    <material name="black" class="/" rgba="0.1 0.1 0.1 1"/>
    <material name="white" class="/" rgba="1 1 1 1"/>
  </asset>
  <worldbody>
    <light name="//unnamed_light_0" class="/" directional="true" pos="0 0 3.5" dir="0 0 -1"/>
    <geom name="floor" class="/" type="plane" size="0 0 0.05" material="groundplane"/>
    <light name="//unnamed_light_1" class="/" mode="targetbodycom" target="torso_link" pos="2 0 2.5"/>
    <body name="pelvis" childclass="h1" pos="0 0 1.06">
      <inertial pos="-0.0002 4e-05 -0.04522" quat="0.4983 0.49945 -0.5005 0.50174" mass="5.39" diaginertia="0.049021 0.044582 0.0082462"/>
      <freejoint name="root"/>
      <body name="left_hip_yaw_link" pos="0 0.0875 -0.1742">
        <inertial pos="-0.04923 0.0001 0.0072" quat="0.69699 0.21919 0.23329 0.64167" mass="2.244" diaginertia="0.0030449 0.0029688 0.001892"/>
        <joint name="left_hip_yaw" axis="0 0 1" range="-0.43 0.43"/>
        <geom name="//unnamed_geom_1" class="collision" type="cylinder" size="0.06 0.035" pos="-0.067 0 0" quat="0.70712 0 0.70709 0"/>
        <body name="left_hip_roll_link" pos="0.039468 0 0">
          <inertial pos="-0.0058 -0.00319 -9e-05" quat="0.043824 0.70721 -0.072908 0.70187" mass="2.232" diaginertia="0.0024326 0.0022533 0.0020549"/>
          <joint name="left_hip_roll" axis="1 0 0" range="-0.43 0.43"/>
          <geom name="//unnamed_geom_2" class="collision" type="cylinder" size="0.05 0.03" pos="0 -0.02 0" quat="1 1 0 0"/>
          <body name="left_hip_pitch_link" pos="0 0.11536 0">
            <inertial pos="0.00746 -0.02346 -0.08193" quat="0.97983 0.051352 -0.016985 -0.19238" mass="4.152" diaginertia="0.08295 0.082146 0.0051091"/>
            <joint name="left_hip_pitch" axis="0 1 0" range="-1.57 1.57"/>
            <geom name="//unnamed_geom_3" class="collision" type="capsule" size="0.03" fromto="0.02 0 -0.4 -0.02 0 0.02"/>
            <geom name="//unnamed_geom_4" class="collision" type="capsule" size="0.03" fromto="0.02 0 -0.4 0.02 0 0.02"/>
            <geom name="//unnamed_geom_5" class="collision" type="cylinder" size="0.05 0.02" pos="0 -0.07 0" quat="1 1 0 0"/>
            <body name="left_knee_link" pos="0 0 -0.4">
              <inertial pos="-0.00136 -0.00512 -0.1384" quat="0.62613 -0.034227 -0.041628 0.77785" mass="1.721" diaginertia="0.012524 0.01231 0.0019428"/>
              <joint name="left_knee" axis="0 1 0" range="-0.26 2.05"/>
              <geom name="//unnamed_geom_6" class="collision" type="capsule" size="0.025" fromto="0.02 0 -0.4 0.02 0 0"/>
              <geom name="//unnamed_geom_7" class="collision" type="sphere" size="0.05" pos="0 0 -0.115"/>
              <body name="left_ankle_link" pos="0 0 -0.4">
                <inertial pos="0.06722 0.00015 -0.04497" quat="0.4891 0.5032 0.56578 0.43297" mass="0.446" diaginertia="0.0022085 0.0021896 0.0002142"/>
                <joint name="left_ankle" axis="0 1 0" range="-0.87 0.52"/>
                <geom name="//unnamed_geom_8" class="foot1"/>
                <geom name="//unnamed_geom_9" class="foot2"/>
                <geom name="//unnamed_geom_10" class="foot3"/>
              </body>
            </body>
          </body>
        </body>
      </body>
      <body name="right_hip_yaw_link" pos="0 -0.0875 -0.1742">
        <inertial pos="-0.04923 -0.0001 0.0072" quat="0.64167 0.23329 0.21919 0.69699" mass="2.244" diaginertia="0.0030449 0.0029688 0.001892"/>
        <joint name="right_hip_yaw" axis="0 0 1" range="-0.43 0.43"/>
        <geom name="//unnamed_geom_11" class="collision" type="cylinder" size="0.06 0.035" pos="-0.067 0 0" quat="0.70712 0 0.70709 0"/>
        <body name="right_hip_roll_link" pos="0.039468 0 0">
          <inertial pos="-0.0058 0.00319 -9e-05" quat="-0.043824 0.70721 0.072908 0.70187" mass="2.232" diaginertia="0.0024326 0.0022533 0.0020549"/>
          <joint name="right_hip_roll" axis="1 0 0" range="-0.43 0.43"/>
          <geom name="//unnamed_geom_12" class="collision" type="cylinder" size="0.05 0.03" pos="0 0.02 0" quat="1 1 0 0"/>
          <body name="right_hip_pitch_link" pos="0 -0.11536 0">
            <inertial pos="0.00746 0.02346 -0.08193" quat="0.97983 -0.051352 -0.016985 0.19238" mass="4.152" diaginertia="0.08295 0.082146 0.0051091"/>
            <joint name="right_hip_pitch" axis="0 1 0" range="-1.57 1.57"/>
            <geom name="//unnamed_geom_13" class="collision" type="capsule" size="0.03" fromto="0.02 0 -0.4 -0.02 0 0.02"/>
            <geom name="//unnamed_geom_14" class="collision" type="capsule" size="0.03" fromto="0.02 0 -0.4 0.02 0 0.02"/>
            <geom name="//unnamed_geom_15" class="collision" type="cylinder" size="0.05 0.02" pos="0 0.07 0" quat="1 1 0 0"/>
            <body name="right_knee_link" pos="0 0 -0.4">
              <inertial pos="-0.00136 0.00512 -0.1384" quat="0.77785 -0.041628 -0.034227 0.62613" mass="1.721" diaginertia="0.012524 0.01231 0.0019428"/>
              <joint name="right_knee" axis="0 1 0" range="-0.26 2.05"/>
              <geom name="//unnamed_geom_16" class="collision" type="capsule" size="0.025" fromto="0.02 0 -0.4 0.02 0 0"/>
              <geom name="//unnamed_geom_17" class="collision" type="sphere" size="0.05" pos="0 0 -0.115"/>
              <body name="right_ankle_link" pos="0 0 -0.4">
                <inertial pos="0.06722 -0.00015 -0.04497" quat="0.43297 0.56578 0.5032 0.4891" mass="0.446" diaginertia="0.0022085 0.0021896 0.0002142"/>
                <joint name="right_ankle" axis="0 1 0" range="-0.87 0.52"/>
                <geom name="//unnamed_geom_18" class="foot1"/>
                <geom name="//unnamed_geom_19" class="foot2"/>
                <geom name="//unnamed_geom_20" class="foot3"/>
              </body>
            </body>
          </body>
        </body>
      </body>
      <body name="torso_link">
        <inertial pos="0.000489 0.002797 0.20484" quat="0.99999 -0.0013081 -0.0028229 -0.003491" mass="17.789" diaginertia="0.48731 0.40963 0.12784"/>
        <geom name="head" class="collision" type="capsule" size="0.06" fromto="0.05 0 0.68 0.05 0 0.6"/>
        <geom name="helmet" class="collision" type="sphere" size="0.073" pos="0.045 0 0.68"/>
        <geom name="torso" class="collision" type="box" size="0.07 0.1 0.22" pos="0 0 0.25"/>
        <geom name="hip" class="collision" type="capsule" size="0.05" fromto="0 -0.1 -0.05 0 0.1 -0.05"/>
        <site name="imu" pos="-0.04452 -0.01891 0.27756"/>
        <body name="left_shoulder_pitch_link" pos="0.0055 0.15535 0.42999" quat="0.9763 0.21644 0 0">
          <inertial pos="0.005045 0.053657 -0.015715" quat="0.81486 0.57924 -0.020107 -0.0093649" mass="1.033" diaginertia="0.0012994 0.00098711 0.0008582"/>
          <body name="left_shoulder_roll_link" pos="-0.0055 0.0565 -0.0165" quat="0.9763 -0.21644 0 0">
            <inertial pos="0.000679 0.00115 -0.094076" quat="0.73249 0.0091718 0.076666 0.67638" mass="0.793" diaginertia="0.0017039 0.0015826 0.0010034"/>
            <geom name="left_shoulder" class="collision" type="capsule" size="0.04" fromto="0 0.01 0.008 0 -0.07 -0.02"/>
            <body name="left_shoulder_yaw_link" pos="0 0 -0.1343">
              <inertial pos="0.01365 0.002767 -0.16266" quat="0.70304 -0.033123 -0.047336 0.7088" mass="0.839" diaginertia="0.0040804 0.0037037 0.00062269"/>
              <geom name="//unnamed_geom_26" class="collision" type="capsule" size="0.03" fromto="0 0 0.15 0 0 -0.2"/>
              <body name="left_elbow_link" pos="0.0185 0 -0.198">
                <inertial pos="0.15908 -0.000144 -0.015776" quat="0.076523 0.72033 0.085312 0.6841" mass="0.669" diaginertia="0.0060183 0.0060058 0.0004083"/>
                <geom name="//unnamed_geom_27" class="collision" type="capsule" size="0.025" fromto="0 0 0 0.28 0 -0.015"/>
                <geom name="//unnamed_geom_28" class="collision" type="sphere" size="0.033" pos="0.28 0 -0.015"/>
              </body>
            </body>
          </body>
        </body>
        <body name="right_shoulder_pitch_link" pos="0.0055 -0.15535 0.42999" quat="0.9763 -0.21644 0 0">
          <inertial pos="0.005045 -0.053657 -0.015715" quat="0.57924 0.81486 0.0093649 0.020107" mass="1.033" diaginertia="0.0012994 0.00098711 0.0008582"/>
          <body name="right_shoulder_roll_link" pos="-0.0055 -0.0565 -0.0165" quat="0.9763 0.21644 0 0">
            <inertial pos="0.000679 -0.00115 -0.094076" quat="0.67638 0.076666 0.0091718 0.73249" mass="0.793" diaginertia="0.0017039 0.0015826 0.0010034"/>
            <geom name="right_shoulder" class="collision" type="capsule" size="0.04" fromto="0 -0.01 0.008 0 0.07 -0.02"/>
            <body name="right_shoulder_yaw_link" pos="0 0 -0.1343">
              <inertial pos="0.01365 -0.002767 -0.16266" quat="0.7088 -0.047336 -0.033123 0.70304" mass="0.839" diaginertia="0.0040804 0.0037037 0.00062269"/>
              <geom name="//unnamed_geom_30" class="collision" type="capsule" size="0.03" fromto="0 0 0.15 0 0 -0.2"/>
              <body name="right_elbow_link" pos="0.0185 0 -0.198">
                <inertial pos="0.15908 0.000144 -0.015776" quat="-0.076523 0.72033 -0.085312 0.6841" mass="0.669" diaginertia="0.0060183 0.0060058 0.0004083"/>
                <geom name="//unnamed_geom_31" class="collision" type="capsule" size="0.025" fromto="0 0 0 0.28 0 -0.015"/>
                <geom name="//unnamed_geom_32" class="collision" type="sphere" size="0.033" pos="0.28 0 -0.015"/>
              </body>
            </body>
          </body>
        </body>
      </body>
    </body>
  </worldbody>
  <contact>
    <exclude name="//unnamed_contact_0" body1="torso_link" body2="left_shoulder_roll_link"/>
    <exclude name="//unnamed_contact_1" body1="torso_link" body2="right_shoulder_roll_link"/>
  </contact>
  <actuator>
    <motor name="left_hip_yaw_motor" class="h1" ctrlrange="-200 200" joint="left_hip_yaw"/>
    <motor name="left_hip_roll_motor" class="h1" ctrlrange="-200 200" joint="left_hip_roll"/>
    <motor name="left_hip_pitch_motor" class="h1" ctrlrange="-200 200" joint="left_hip_pitch"/>
    <motor name="left_knee_motor" class="h1" ctrlrange="-300 300" joint="left_knee"/>
    <motor name="left_ankle_motor" class="h1" ctrlrange="-40 40" joint="left_ankle"/>
    <motor name="right_hip_yaw_motor" class="h1" ctrlrange="-200 200" joint="right_hip_yaw"/>
    <motor name="right_hip_roll_motor" class="h1" ctrlrange="-200 200" joint="right_hip_roll"/>
    <motor name="right_hip_pitch_motor" class="h1" ctrlrange="-200 200" joint="right_hip_pitch"/>
    <motor name="right_knee_motor" class="h1" ctrlrange="-300 300" joint="right_knee"/>
    <motor name="right_ankle_motor" class="h1" ctrlrange="-40 40" joint="right_ankle"/>
  </actuator>
</mujoco>
